<mujoco model="z-bot2_fe_urdf">
  <option iterations="50" timestep="0.001" solver="PGS" gravity="0 0 -9.81" />

  <compiler angle="radian" meshdir="meshes" eulerseq="zyx" autolimits="true" />

  <default>
    <joint limited="true" damping="0.01" armature="0.01" frictionloss="0.01" />
    <geom condim="4" contype="1" conaffinity="15" friction="0.9 0.2 0.2" solref="0.001 2" />
    <motor ctrllimited="true" />
    <equality solref="0.001 2" />
    <default class="visualgeom">
      <geom material="visualgeom" condim="1" contype="0" conaffinity="0" />
    </default>
  </default>

  <asset>
    <mesh name="Z-BOT2_MASTER-BODY-SKELETON" file="Z-BOT2_MASTER-BODY-SKELETON.stl" />
    <mesh name="Z-BOT2-MASTER-SHOULDER2" file="Z-BOT2-MASTER-SHOULDER2.stl" />
    <mesh name="Z-BOT2-MASTER-SHOULDER2_2" file="Z-BOT2-MASTER-SHOULDER2_2.stl" />
    <mesh name="U-HIP-L" file="U-HIP-L.stl" />
    <mesh name="U-HIP-R" file="U-HIP-R.stl" />
    <mesh name="3215_1Flange" file="3215_1Flange.stl" />
    <mesh name="3215_1Flange_2" file="3215_1Flange_2.stl" />
    <mesh name="3215_BothFlange" file="3215_BothFlange.stl" />
    <mesh name="3215_BothFlange_2" file="3215_BothFlange_2.stl" />
    <mesh name="3215_BothFlange_3" file="3215_BothFlange_3.stl" />
    <mesh name="3215_BothFlange_4" file="3215_BothFlange_4.stl" />
    <mesh name="R-ARM-MIRROR-1" file="R-ARM-MIRROR-1.stl" />
    <mesh name="L-ARM-MIRROR_1" file="L-ARM-MIRROR_1.stl" />
    <mesh name="3215_BothFlange_5" file="3215_BothFlange_5.stl" />
    <mesh name="3215_BothFlange_6" file="3215_BothFlange_6.stl" />
    <mesh name="FINGER_1" file="FINGER_1.stl" />
    <mesh name="FINGER_1_2" file="FINGER_1_2.stl" />
    <mesh name="FOOT" file="FOOT.stl" />
    <mesh name="FOOT_2" file="FOOT_2.stl" />
    <texture name="texplane" type="2d" builtin="checker" rgb1=".0 .0 .0" rgb2=".8 .8 .8" width="100" height="100" />
    <material name="matplane" reflectance="0." texture="texplane" texrepeat="1 1" texuniform="true" />
    <material name="visualgeom" rgba="0.5 0.9 0.2 1" />
  </asset>

  <worldbody>
    <light directional="true" diffuse="0.4 0.4 0.4" specular="0.1 0.1 0.1" pos="0 0 5.0" dir="0 0 -1" castshadow="false" />
    <light directional="true" diffuse="0.6 0.6 0.6" specular="0.2 0.2 0.2" pos="0 0 4" dir="0 0 -1" />
    <geom name="ground" type="plane" pos="0 0 0" size="100 100 0.001" quat="1 0 0 0" material="matplane" condim="3" conaffinity="15" />
    <camera name="fixed" pos="0 -3.0 0.94486556113872" xyaxes="1 0 0 0 0 1" />
    <camera name="track" mode="trackcom" pos="0 -3.0 0.94486556113872" xyaxes="1 0 0 0 0 1" />
    <body name="root" pos="0 0 0.44486556113871994" quat="1 0 0 0">
      <freejoint name="root" />
      <site name="imu" size="0.01" pos="0 0 0" />
      <geom name="Z-BOT2_MASTER-BODY-SKELETON_collision" type="mesh" rgba="0.494118 0.623529 0.74902 1" mesh="Z-BOT2_MASTER-BODY-SKELETON" contype="1" conaffinity="0" density="0" group="1" class="visualgeom" />
      <geom type="mesh" rgba="0.494118 0.623529 0.74902 1" mesh="Z-BOT2_MASTER-BODY-SKELETON" />
      <body name="Z-BOT2-MASTER-SHOULDER2" pos="0.055995 -0.00960999 -0.00952781" quat="1.64085e-08 1.64085e-08 -0.707107 -0.707107">
        <inertial pos="-0.012788 0.00137412 0.0188002" quat="0.707107 0 0 0.707107" mass="0.0240976" diaginertia="7.79811e-06 7.41938e-06 2.98246e-06" />
        <joint name="left_shoulder_yaw" pos="0 0 0" axis="0 0 1" range="-1.0472 0" actuatorfrcrange="-2 2" />
        <geom name="Z-BOT2-MASTER-SHOULDER2_collision" type="mesh" rgba="0.364706 0.360784 0.74902 1" mesh="Z-BOT2-MASTER-SHOULDER2" contype="1" conaffinity="0" density="0" group="1" class="visualgeom" />
        <geom type="mesh" rgba="0.364706 0.360784 0.74902 1" mesh="Z-BOT2-MASTER-SHOULDER2" />
        <body name="3215_1Flange" pos="-0.019845 -0.0049 0.0188" quat="0.5 -0.5 0.5 -0.5">
          <inertial pos="0.0336416 0.00043799 -0.0199632" quat="-0.0203391 0.719069 -0.00514056 0.694622" mass="0.18196" diaginertia="0.000232059 0.000228303 5.36054e-05" />
          <joint name="left_shoulder_pitch" pos="0 0 0" axis="0 0 1" range="-1.5708 1.5708" actuatorfrcrange="-2 2" />
          <geom name="3215_1Flange_collision" type="mesh" rgba="0.74902 0.498039 0.72549 1" mesh="3215_1Flange" contype="1" conaffinity="0" density="0" group="1" class="visualgeom" />
          <geom type="mesh" rgba="0.74902 0.498039 0.72549 1" mesh="3215_1Flange" />
          <body name="R-ARM-MIRROR-1" pos="0.0929838 0.0187997 -0.0186004" quat="1.89469e-08 1.89469e-08 0.707107 0.707107">
            <inertial pos="-0.0511191 0.00114955 -0.0177425" quat="0.507993 0.552378 0.440704 0.492545" mass="0.186073" diaginertia="0.000221156 0.000201116 5.79354e-05" />
            <joint name="left_elbow" pos="0 0 0" axis="0 0 1" range="-1.5708 0" actuatorfrcrange="-2 2" />
            <geom name="R-ARM-MIRROR-1_collision" type="mesh" rgba="0.647059 0.647059 0.647059 1" mesh="R-ARM-MIRROR-1" contype="1" conaffinity="0" density="0" group="1" class="visualgeom" />
            <geom type="mesh" rgba="0.647059 0.647059 0.647059 1" mesh="R-ARM-MIRROR-1" />
            <body name="FINGER_1" pos="-0.0662057 -0.0117782 0.000259717" quat="1.90085e-08 0.573576 0.819152 1.33099e-08">
              <inertial pos="-0.0106709 -0.0289847 0.0187998" quat="0.704186 0.704191 -0.0641729 -0.0641724" mass="0.044318" diaginertia="2.36691e-05 1.62899e-05 9.73666e-06" />
              <joint name="left_gripper" pos="0 0 0" axis="0 0 1" range="0 0.523599" actuatorfrcrange="-2 2" />
              <geom name="FINGER_1_collision" type="mesh" rgba="0.627451 0.627451 0.627451 1" mesh="FINGER_1" contype="1" conaffinity="0" density="0" group="1" class="visualgeom" />
              <geom type="mesh" rgba="0.627451 0.627451 0.627451 1" mesh="FINGER_1" />
            </body>
          </body>
        </body>
      </body>
      <body name="Z-BOT2-MASTER-SHOULDER2_2" pos="-0.055995 -0.00960999 -0.00952781" quat="0.707107 -0.707107 -3.2817e-08 3.2817e-08">
        <inertial pos="-0.012788 -0.00137412 0.0187998" quat="0.707107 0 0 0.707107" mass="0.0240976" diaginertia="7.79811e-06 7.41938e-06 2.98246e-06" />
        <joint name="right_shoulder_yaw" pos="0 0 0" axis="0 0 1" range="0 1.0472" actuatorfrcrange="-2 2" />
        <geom name="Z-BOT2-MASTER-SHOULDER2_collision_2" type="mesh" rgba="0.364706 0.360784 0.74902 1" mesh="Z-BOT2-MASTER-SHOULDER2_2" contype="1" conaffinity="0" density="0" group="1" class="visualgeom" />
        <geom type="mesh" rgba="0.364706 0.360784 0.74902 1" mesh="Z-BOT2-MASTER-SHOULDER2_2" />
        <body name="3215_1Flange_2" pos="-0.019845 0.0049 0.0188" quat="0.5 0.5 0.5 0.5">
          <inertial pos="0.0336416 -0.000432534 -0.0199683" quat="0.0200704 0.719158 0.00477883 0.69454" mass="0.18196" diaginertia="0.000232062 0.000228301 5.35996e-05" />
          <joint name="right_shoulder_pitch" pos="0 0 0" axis="0 0 1" range="-1.5708 1.5708" actuatorfrcrange="-2 2" />
          <geom name="3215_1Flange_collision_2" type="mesh" rgba="0.74902 0.498039 0.72549 1" mesh="3215_1Flange_2" contype="1" conaffinity="0" density="0" group="1" class="visualgeom" />
          <geom type="mesh" rgba="0.74902 0.498039 0.72549 1" mesh="3215_1Flange_2" />
          <body name="L-ARM-MIRROR_1" pos="0.0929838 -0.0187997 -0.0186004" quat="0.5 -0.5 -0.5 -0.5">
            <inertial pos="0.00114428 0.0511233 0.0177642" quat="0.701318 0.708392 -0.0109354 -0.0788334" mass="0.186073" diaginertia="0.000221286 0.000201258 5.79557e-05" />
            <joint name="right_elbow" pos="0 0 0" axis="0 0 1" range="-1.5708 0" actuatorfrcrange="-2 2" />
            <geom name="L-ARM-MIRROR_1_collision" type="mesh" rgba="0.627451 0.627451 0.627451 1" mesh="L-ARM-MIRROR_1" contype="1" conaffinity="0" density="0" group="1" class="visualgeom" />
            <geom type="mesh" rgba="0.627451 0.627451 0.627451 1" mesh="L-ARM-MIRROR_1" />
            <body name="FINGER_1_2" pos="-0.0117782 0.0662057 -0.000259719" quat="0.984808 0 0 0.173648">
              <inertial pos="-0.0106709 0.0289847 0.0187995" quat="0.704186 0.704191 0.0641729 0.0641724" mass="0.044318" diaginertia="2.36691e-05 1.62899e-05 9.73666e-06" />
              <joint name="right_gripper" pos="0 0 0" axis="0 0 1" range="-0.523599 0" actuatorfrcrange="-2 2" />
              <geom name="FINGER_1_collision_2" type="mesh" rgba="0.627451 0.627451 0.627451 1" mesh="FINGER_1_2" contype="1" conaffinity="0" density="0" group="1" class="visualgeom" />
              <geom type="mesh" rgba="0.627451 0.627451 0.627451 1" mesh="FINGER_1_2" />
            </body>
          </body>
        </body>
      </body>
      <body name="U-HIP-L" pos="0.0428082 0.00773508 -0.0844184" quat="0 2.32051e-08 1 2.32051e-08">
        <inertial pos="-0.00116062 -0.0043962 0.0353962" quat="0.921476 0.220762 0.207667 0.242942" mass="0.0471324" diaginertia="3.44774e-05 3.0413e-05 1.26353e-05" />
        <joint name="left_hip_yaw" pos="0 0 0" axis="0 0 1" range="-1.0472 1.0472" actuatorfrcrange="-2 2" />
        <geom name="U-HIP-L_collision" type="mesh" rgba="0.768627 0.886275 0.952941 1" mesh="U-HIP-L" contype="1" conaffinity="0" density="0" group="1" class="visualgeom" />
        <geom type="mesh" rgba="0.768627 0.886275 0.952941 1" mesh="U-HIP-L" />
        <body name="3215_BothFlange" pos="0 0.0186997 0.0564" quat="0.707107 -0.707107 0 0">
          <inertial pos="0.0123316 -0.00899712 -0.0185084" quat="0.145714 0.695819 0.101439 0.695926" mass="0.0682953" diaginertia="2.54323e-05 2.35496e-05 1.92309e-05" />
          <joint name="left_hip_roll" pos="0 0 0" axis="0 0 1" range="-1.5708 0" actuatorfrcrange="-2 2" />
          <geom name="3215_BothFlange_collision" type="mesh" rgba="1 0 0 1" mesh="3215_BothFlange" contype="1" conaffinity="0" density="0" group="1" class="visualgeom" />
          <geom type="mesh" rgba="1 0 0 1" mesh="3215_BothFlange" />
          <body name="3215_BothFlange_3" pos="-0.00739965 -0.032 -0.0179" quat="0.5 0.5 -0.5 -0.5">
            <inertial pos="0.0436622 -0.00285684 -0.0185251" quat="0.501297 0.512271 0.501533 0.484504" mass="0.143337" diaginertia="0.000148209 0.000127579 4.86495e-05" />
            <joint name="left_hip_pitch" pos="0 0 0" axis="0 0 1" range="-1.5708 1.5708" actuatorfrcrange="-2 2" />
            <geom name="3215_BothFlange_collision_3" type="mesh" rgba="1 0 0 1" mesh="3215_BothFlange_3" contype="1" conaffinity="0" density="0" group="1" class="visualgeom" />
            <geom type="mesh" rgba="1 0 0 1" mesh="3215_BothFlange_3" />
            <body name="3215_BothFlange_5" pos="0.1 0.01 -0.000259724" quat="1 2.32051e-08 2.32051e-08 0">
              <inertial pos="0.05 2.60326e-09 -0.0179884" quat="0.49947 0.500681 0.50053 0.499318" mass="0.128213" diaginertia="0.000154386 0.000145408 3.53654e-05" />
              <joint name="left_knee" pos="0 0 0" axis="0 0 1" range="0 2.0944" actuatorfrcrange="-2 2" />
              <geom name="3215_BothFlange_collision_5" type="mesh" rgba="1 0 0 1" mesh="3215_BothFlange_5" contype="1" conaffinity="0" density="0" group="1" class="visualgeom" />
              <geom type="mesh" rgba="1 0 0 1" mesh="3215_BothFlange_5" />
              <body name="FOOT" pos="0.1 3.36408e-09 -0.000199995" quat="-1.64085e-08 -0.707107 -0.707107 1.64085e-08">
                <inertial pos="-0.0150779 0.0278353 0.0187" quat="0.507219 0.507219 0.492675 0.492675" mass="0.27814" diaginertia="0.000205404 0.000181871 4.48069e-05" />
                <joint name="left_ankle" pos="0 0 0" axis="0 0 1" range="-1.5708 1.5708" actuatorfrcrange="-2 2" />
                <geom name="FOOT_collision" type="mesh" rgba="0.627451 0.627451 0.627451 1" mesh="FOOT" contype="1" conaffinity="0" density="0" group="1" class="visualgeom" />
                <geom type="mesh" rgba="0.627451 0.627451 0.627451 1" mesh="FOOT" />
              </body>
            </body>
          </body>
        </body>
      </body>
      <body name="U-HIP-R" pos="-0.0428681 0.00773508 -0.0844184" quat="0 2.32051e-08 1 2.32051e-08">
        <inertial pos="0.00116062 -0.0043962 0.0353962" quat="0.921476 0.220762 -0.207667 -0.242942" mass="0.0471324" diaginertia="3.44774e-05 3.0413e-05 1.26353e-05" />
        <joint name="right_hip_yaw" pos="0 0 0" axis="0 0 1" range="-1.0472 1.0472" actuatorfrcrange="-2 2" />
        <geom name="U-HIP-R_collision" type="mesh" rgba="0.768627 0.886275 0.952941 1" mesh="U-HIP-R" contype="1" conaffinity="0" density="0" group="1" class="visualgeom" />
        <geom type="mesh" rgba="0.768627 0.886275 0.952941 1" mesh="U-HIP-R" />
        <body name="3215_BothFlange_2" pos="0 -0.0186997 0.0564" quat="-1.64085e-08 1.64085e-08 0.707107 -0.707107">
          <inertial pos="0.0123316 -0.00898328 -0.0178111" quat="-0.0705027 0.700607 -0.114113 0.700826" mass="0.0682953" diaginertia="2.5341e-05 2.36252e-05 1.92157e-05" />
          <joint name="right_hip_roll" pos="0 0 0" axis="0 0 1" range="-1.5708 0" actuatorfrcrange="-2 2" />
          <geom name="3215_BothFlange_collision_2" type="mesh" rgba="1 0 0 1" mesh="3215_BothFlange_2" contype="1" conaffinity="0" density="0" group="1" class="visualgeom" />
          <geom type="mesh" rgba="1 0 0 1" mesh="3215_BothFlange_2" />
          <body name="3215_BothFlange_4" pos="-0.00739965 -0.032 -0.0188997" quat="0.5 0.5 -0.5 -0.5">
            <inertial pos="0.0436622 0.00286343 -0.0185366" quat="0.484624 0.501567 0.512165 0.501256" mass="0.143337" diaginertia="0.000148208 0.000127573 4.86473e-05" />
            <joint name="right_hip_pitch" pos="0 0 0" axis="0 0 1" range="-1.5708 1.5708" actuatorfrcrange="-2 2" />
            <geom name="3215_BothFlange_collision_4" type="mesh" rgba="1 0 0 1" mesh="3215_BothFlange_4" contype="1" conaffinity="0" density="0" group="1" class="visualgeom" />
            <geom type="mesh" rgba="1 0 0 1" mesh="3215_BothFlange_4" />
            <body name="3215_BothFlange_6" pos="0.1 -0.01 -0.000259715" quat="1 2.32051e-08 -2.32051e-08 0">
              <inertial pos="0.05 2.88121e-09 -0.0178883" quat="0.500076 0.500076 0.499924 0.499924" mass="0.128213" diaginertia="0.000154544 0.000145407 3.5524e-05" />
              <joint name="right_knee" pos="0 0 0" axis="0 0 1" range="-2.0944 0" actuatorfrcrange="-2 2" />
              <geom name="3215_BothFlange_collision_6" type="mesh" rgba="1 0 0 1" mesh="3215_BothFlange_6" contype="1" conaffinity="0" density="0" group="1" class="visualgeom" />
              <geom type="mesh" rgba="1 0 0 1" mesh="3215_BothFlange_6" />
              <body name="FOOT_2" pos="0.1 3.36408e-09 4.73152e-09" quat="1.64085e-08 -0.707107 0.707107 -4.92255e-08">
                <inertial pos="-0.0150779 -0.0278353 0.0187" quat="0.492675 0.492675 0.507219 0.507219" mass="0.27814" diaginertia="0.000205404 0.000181871 4.48069e-05" />
                <joint name="right_ankle" pos="0 0 0" axis="0 0 1" range="-1.5708 1.5708" actuatorfrcrange="-2 2" />
                <geom name="FOOT_collision_2" type="mesh" rgba="0.627451 0.627451 0.627451 1" mesh="FOOT_2" contype="1" conaffinity="0" density="0" group="1" class="visualgeom" />
                <geom type="mesh" rgba="0.627451 0.627451 0.627451 1" mesh="FOOT_2" />
              </body>
            </body>
          </body>
        </body>
      </body>
    </body>
  </worldbody>

  <actuator>
    <motor name="left_shoulder_yaw" joint="left_shoulder_yaw" ctrllimited="true" ctrlrange="-2 2" gear="1" />
    <motor name="left_shoulder_pitch" joint="left_shoulder_pitch" ctrllimited="true" ctrlrange="-2 2" gear="1" />
    <motor name="left_elbow" joint="left_elbow" ctrllimited="true" ctrlrange="-2 2" gear="1" />
    <motor name="left_gripper" joint="left_gripper" ctrllimited="true" ctrlrange="-2 2" gear="1" />
    <motor name="right_shoulder_yaw" joint="right_shoulder_yaw" ctrllimited="true" ctrlrange="-2 2" gear="1" />
    <motor name="right_shoulder_pitch" joint="right_shoulder_pitch" ctrllimited="true" ctrlrange="-2 2" gear="1" />
    <motor name="right_elbow" joint="right_elbow" ctrllimited="true" ctrlrange="-2 2" gear="1" />
    <motor name="right_gripper" joint="right_gripper" ctrllimited="true" ctrlrange="-2 2" gear="1" />
    <motor name="left_hip_yaw" joint="left_hip_yaw" ctrllimited="true" ctrlrange="-2 2" gear="1" />
    <motor name="left_hip_roll" joint="left_hip_roll" ctrllimited="true" ctrlrange="-2 2" gear="1" />
    <motor name="left_hip_pitch" joint="left_hip_pitch" ctrllimited="true" ctrlrange="-2 2" gear="1" />
    <motor name="left_knee" joint="left_knee" ctrllimited="true" ctrlrange="-2 2" gear="1" />
    <motor name="left_ankle" joint="left_ankle" ctrllimited="true" ctrlrange="-2 2" gear="1" />
    <motor name="right_hip_yaw" joint="right_hip_yaw" ctrllimited="true" ctrlrange="-2 2" gear="1" />
    <motor name="right_hip_roll" joint="right_hip_roll" ctrllimited="true" ctrlrange="-2 2" gear="1" />
    <motor name="right_hip_pitch" joint="right_hip_pitch" ctrllimited="true" ctrlrange="-2 2" gear="1" />
    <motor name="right_knee" joint="right_knee" ctrllimited="true" ctrlrange="-2 2" gear="1" />
    <motor name="right_ankle" joint="right_ankle" ctrllimited="true" ctrlrange="-2 2" gear="1" />
  </actuator>

  <sensor>
    <actuatorpos name="left_shoulder_yaw_p" actuator="left_shoulder_yaw" />
    <actuatorvel name="left_shoulder_yaw_v" actuator="left_shoulder_yaw" />
    <actuatorfrc name="left_shoulder_yaw_f" actuator="left_shoulder_yaw" noise="0.001" />
    <actuatorpos name="left_shoulder_pitch_p" actuator="left_shoulder_pitch" />
    <actuatorvel name="left_shoulder_pitch_v" actuator="left_shoulder_pitch" />
    <actuatorfrc name="left_shoulder_pitch_f" actuator="left_shoulder_pitch" noise="0.001" />
    <actuatorpos name="left_elbow_p" actuator="left_elbow" />
    <actuatorvel name="left_elbow_v" actuator="left_elbow" />
    <actuatorfrc name="left_elbow_f" actuator="left_elbow" noise="0.001" />
    <actuatorpos name="left_gripper_p" actuator="left_gripper" />
    <actuatorvel name="left_gripper_v" actuator="left_gripper" />
    <actuatorfrc name="left_gripper_f" actuator="left_gripper" noise="0.001" />
    <actuatorpos name="right_shoulder_yaw_p" actuator="right_shoulder_yaw" />
    <actuatorvel name="right_shoulder_yaw_v" actuator="right_shoulder_yaw" />
    <actuatorfrc name="right_shoulder_yaw_f" actuator="right_shoulder_yaw" noise="0.001" />
    <actuatorpos name="right_shoulder_pitch_p" actuator="right_shoulder_pitch" />
    <actuatorvel name="right_shoulder_pitch_v" actuator="right_shoulder_pitch" />
    <actuatorfrc name="right_shoulder_pitch_f" actuator="right_shoulder_pitch" noise="0.001" />
    <actuatorpos name="right_elbow_p" actuator="right_elbow" />
    <actuatorvel name="right_elbow_v" actuator="right_elbow" />
    <actuatorfrc name="right_elbow_f" actuator="right_elbow" noise="0.001" />
    <actuatorpos name="right_gripper_p" actuator="right_gripper" />
    <actuatorvel name="right_gripper_v" actuator="right_gripper" />
    <actuatorfrc name="right_gripper_f" actuator="right_gripper" noise="0.001" />
    <actuatorpos name="left_hip_yaw_p" actuator="left_hip_yaw" />
    <actuatorvel name="left_hip_yaw_v" actuator="left_hip_yaw" />
    <actuatorfrc name="left_hip_yaw_f" actuator="left_hip_yaw" noise="0.001" />
    <actuatorpos name="left_hip_roll_p" actuator="left_hip_roll" />
    <actuatorvel name="left_hip_roll_v" actuator="left_hip_roll" />
    <actuatorfrc name="left_hip_roll_f" actuator="left_hip_roll" noise="0.001" />
    <actuatorpos name="left_hip_pitch_p" actuator="left_hip_pitch" />
    <actuatorvel name="left_hip_pitch_v" actuator="left_hip_pitch" />
    <actuatorfrc name="left_hip_pitch_f" actuator="left_hip_pitch" noise="0.001" />
    <actuatorpos name="left_knee_p" actuator="left_knee" />
    <actuatorvel name="left_knee_v" actuator="left_knee" />
    <actuatorfrc name="left_knee_f" actuator="left_knee" noise="0.001" />
    <actuatorpos name="left_ankle_p" actuator="left_ankle" />
    <actuatorvel name="left_ankle_v" actuator="left_ankle" />
    <actuatorfrc name="left_ankle_f" actuator="left_ankle" noise="0.001" />
    <actuatorpos name="right_hip_yaw_p" actuator="right_hip_yaw" />
    <actuatorvel name="right_hip_yaw_v" actuator="right_hip_yaw" />
    <actuatorfrc name="right_hip_yaw_f" actuator="right_hip_yaw" noise="0.001" />
    <actuatorpos name="right_hip_roll_p" actuator="right_hip_roll" />
    <actuatorvel name="right_hip_roll_v" actuator="right_hip_roll" />
    <actuatorfrc name="right_hip_roll_f" actuator="right_hip_roll" noise="0.001" />
    <actuatorpos name="right_hip_pitch_p" actuator="right_hip_pitch" />
    <actuatorvel name="right_hip_pitch_v" actuator="right_hip_pitch" />
    <actuatorfrc name="right_hip_pitch_f" actuator="right_hip_pitch" noise="0.001" />
    <actuatorpos name="right_knee_p" actuator="right_knee" />
    <actuatorvel name="right_knee_v" actuator="right_knee" />
    <actuatorfrc name="right_knee_f" actuator="right_knee" noise="0.001" />
    <actuatorpos name="right_ankle_p" actuator="right_ankle" />
    <actuatorvel name="right_ankle_v" actuator="right_ankle" />
    <actuatorfrc name="right_ankle_f" actuator="right_ankle" noise="0.001" />
    <framequat name="orientation" objtype="site" noise="0.001" objname="imu" />
    <gyro name="angular-velocity" site="imu" noise="0.005" cutoff="34.9" />
  </sensor>
</mujoco>